# 47장 에러 처리

## 47.1 에러 처리의 필요성

- 에러는 언제나 발생할 수 있지만 발생한 에러에 대해 대처하지 않고 방치하면 프로그램은 강제 종료된다.

- try...catch문을 사용해 발생한 에러에 적절하게 대응하면 프로그램이 강제 종료되지 않고 계속해서 코드를 실행시킬 수 있다.

- 직접적으로 에러를 발생하지는 않는 예외 상황이 발생할 수 있지만 이에 적절하게 대응하지 않으면 에러로 이어질 가능성이 크다.

- 에러가 발생하지 않는 코드를 작성하는 것이 이상적이지만 그것은 불가능하기 때문에 우리가 작성한 코드에서는 언제나 에러나 예외적인 상황이 발행할 수 있다는 것을 전제하고 이에 대응하는 코드를 작성하는 것이 중요하다.

## 47.2 try... catch... finally문

- 에러 처리를 구현하는 방법은 크게 두 가지가 있는데, 첫번째는 예외적인 상황이 발생하면 반환하는 값을 if문이나 단축 평가 또는 옵셔널 체이닝 연산자를 통해 확인해서 처리하는 방법이다.

- 두번째는 에러 처리 코드를 미리 등록해 주고 에러가 발생하면 에러 처리 코드로 점프하도록 하는 방법이다.

- try.. catch... finally문은 두번째 방법이고, 일반적으로 이 방법을 에러 처리라고 한다.

```js
try {
  // 실행 할 코드(에러가 발생할 가능성이 있는 코드)
} catch (err) {
  // try코드 블록에서 에러가 발생하면 이 코드 블록의 코드가 실행된다.
  // err에는 try 코드 블록에서 발생한 Error 객체가 전달된다.
} finally {
  // 에러 발생과 상관없이 반드시 한 번 실행된다.
}
```

- try 코드 블록에 포함된 문 중에서 에러가 발생하면 발생한 에러는 catch 문의 err변수에 전달되고 catch 코드 블록이 실행된다.

- err변수는 catch 코드 블록에서만 유효하다.

- finally 코드 블록은 에러 발생과 상관없이 반드시 한 번 실행된다.

- try... catch... finally문으로 에러 처리를 하면 프로그램이 강제 종료 되지 않는다.

## 47.3 Error 객체

- Error 생성자 함수는 에러 객체를 생성한다.

```js
const error = new Error('invalid');
```

- Error 생성자 함수가 생성한 에러 객체는 message 프로퍼티와 stack 프로퍼티를 갖는다.

- message 프로퍼티의 값은 Error 생성자 함수에 인수로 전달한 에러 메시지이고, stack 프로퍼티의 값은 에러를 발생시킨 콜스택의 호출 정보를 나타내는 문자열이며 디버깅 목적으로 사용한다.

- JS는 Error 생성자 함수를 포함해 7가지의 에러 객체를 생성할 수 잇는 Error 생성자 함수를 제공한다.

- SyntaxError, ReferenceError, TypeError, RangeError, URIError, EvalError 생성자 함수가 생성한 에러 객체의 프로토타입은 모두 Error.prototype을 상속받는다.

## 47.4 throw 문

- 에러 객체를 생성한다고 에러가 발생하는 것은 아니다.

- try 코드 블록에서 Error 객체를 생성한다고 에러가 발생하지 않기 때문에 throw문으로 에러 객체를 던져야 한다.

```js
throw 표현식;
```

- throw 문의 표현식은 어떤 값이라도 상관없지만 일반적릉로 에러 객체를 지정한다.

- 에러를 던지면 catch 문의 에러 변수가 생성되고 던져진 에러 객체가 할당된다. 이후 catch 코드 블록이 실행된다.

## 47.5 에러의 전파

- 에러는 호출자 방향으로 전파된다. 즉, 콜 스택의 아래 방향으로 전파된다.

```js
const foo = () => {
  throw Error('foo에서 발생한 에러'); // 4
};

const bar = () => {
  foo(); // 3
};

const baz = () => {
  bar(); // 2
};

try {
  baz(); // 1
} catch (err) {
  console.log(err);
}
```

- 1에서 baz함수를 호출하면 2에서 bar함수가 호출되고 3에서 foo함수가 호출되고 foo함수는 4에서 에러를 throw한다. 이때 foo 함수가 throw한 에러는 다음과 같이 호출자에게 전파되어 전역에서 캐치된다.

- 이처럼 throw된 에러를 캐치하지 않으면 호출자 방향으로 전파되고 어디에서도 캐치하지 않으면 프로그램은 강제 종료된다.

- 비동기 함수인 setTimeout이나 프로미스 후속 처리 메서드의 콜백 함수는 호출자가 없다.
